#VRML_SIM R2023a utf8
# licence: MIT
# license url: https://choosealicense.com/licenses/mit/
# Publiushes Simulation Time to Smart Home Manager. ADD ONLY ONCE!
# template language: javascript
PROTO SH_SimulationTime [
    field SFString      name "SimTime"
    field SFVec3f       translation 0 0 1.5
    field SFRotation    rotation    0 1 0 -1.5708
    field SFFloat       size       0.8
    unconnectedField SFFloat  hour 21
    unconnectedField SFFloat  minute 45
    unconnectedField SFFloat  second 30
  ]
{
    Robot {
    name IS name
    translation IS translation
    rotation IS rotation
      children [
    Transform {
      translation -0.1 0 0
      scale %<= fields.size.value >% %<=fields.size.value>% 1 
      children [
        HingeJoint {
          jointParameters HingeJointParameters {
            position 3.0377106565111145
            axis 0 0 -1
          }
          device [
            RotationalMotor {
              name "second motor"
            }
          ]
          endPoint Solid {
            rotation 0 0 -1 3.0377106565111145
            children [
              Transform {
                translation 0.25 0 0.03
                children [
                  Shape {
                    appearance PBRAppearance {
                      baseColor 1 0 0
                    }
                    geometry Box {
                      size 0.5 0.005 0.005
                    }
                  }
                ]
              }
            ]
            name "solid(2)"
          }
        }
        HingeJoint {
          jointParameters HingeJointParameters {
            position 5.286616266924782
            axis 0 0 -1
          }
          device [
            RotationalMotor {
              name "minute motor"
            }
          ]
          endPoint Solid {
            rotation 0 0 -1 5.286616266924782
            children [
              Transform {
                translation 0.25 0 0.03
                children [
                  Shape {
                    appearance PBRAppearance {
                      baseColor 0.137255 0.137255 0.137255
                    }
                    geometry Box {
                      size 0.5 0.02 0.005
                    }
                  }
                ]
              }
            ]
          }
        }
        HingeJoint {
          jointParameters HingeJointParameters {
            position 5.152940335961771
            axis 0 0 -1
          }
          device [
            RotationalMotor {
              name "hour motor"
            }
          ]
          endPoint Solid {
            rotation 0 0 -1 5.152940335961771
            children [
              Transform {
                translation 0.2 0 0.04
                children [
                  Shape {
                    appearance PBRAppearance {
                      baseColor 0.137255 0.137255 0.137255
                    }
                    geometry Box {
                      size 0.4 0.02 0.005
                    }
                  }
                ]
              }
            ]
            name "solid(1)"
          }
        }
        Transform {
          translation 0 0.5 0
          rotation 0 0 1 1.5707996938995747
          children [
            Shape {
              appearance PBRAppearance {
              }
              geometry Box {
                size 0.1 0.05 0.05
              }
            }
          ]
        }
        Transform {
          translation 0 -0.5 0
          rotation 0 0 1 1.5707996938995747
          children [
            Shape {
              appearance PBRAppearance {
              }
              geometry Box {
                size 0.1 0.05 0.05
              }
            }
          ]
        }
        Transform {
          translation 0.5 0 0
          children [
            Shape {
              appearance PBRAppearance {
              }
              geometry Box {
                size 0.1 0.05 0.05
              }
            }
          ]
        }
        Transform {
          translation -0.5 0 0
          children [
            Shape {
              appearance PBRAppearance {
              }
              geometry Box {
                size 0.1 0.05 0.05
              }
            }
          ]
        }
        Shape {
          appearance PBRAppearance {
            baseColor 0.137255 0.137255 0.137255
          }
          geometry Cylinder {
            height 0.05
            radius 0.05
          }
        }
      ]
    }
  ]
  controller "SimTimeController"
  window "sh_simtime_window"
  }
}