#VRML_SIM R2022a utf8
# licence: MIT
# license url: https://choosealicense.com/licenses/mit/
# Smart Home controllable shutters
# template language: javascript

PROTO SH_Shutter [
    field SFString      name "shutter"
    field SFVec3f       translation 0 0 1.4
    field SFRotation    rotation    0 1 0 0
    field SFVec3f ShutterControllerPosition 0 0 1.4
    field SFVec3f ShutterControllerSize 0.005 0.1 0.1
    field SFFloat ShutterPosition 0
    field SFFloat ShutterHeight 1.4
    field SFFloat ShutterWidth 0.8
    field SFFloat ShutterThickness 0.05
    field SFFloat ShutterTransparency 0
    unconnectedField SFBool stop TRUE
    unconnectedField SFBool up TRUE
    unconnectedField SFBool down TRUE

  ]
{
Robot {
  translation IS translation
  rotation IS rotation
  name IS name
  children [
    SolidBox { 
        translation IS ShutterControllerPosition
        name "ShutterButtons"
        size IS ShutterControllerSize
        appearance PBRAppearance {
          baseColor 0.8 0.8 0.8
          metalness 0
          transparency 0
        }
        castShadows IS castShadows
      }
    Emitter {
      channel 1
    }
    SliderJoint {
      jointParameters JointParameters {
        position IS ShutterPosition
      }
      device [
        PositionSensor {
        }
        Brake {
        }
        LinearMotor {
          maxVelocity 0.1
          maxPosition IS ShutterHeight
        }
      ]
      endPoint Solid {
        translation %<= fields.ShutterThickness.value >% 0 %<= fields.ShutterHeight.value * 0.5 >%
        children [
          Transform {
            children [
              Shape {
                appearance PBRAppearance {
                  roughness 1
                  transparency IS ShutterTransparency
                }
                geometry Box {
                  size %<= fields.ShutterThickness.value >% %<= fields.ShutterWidth.value >% %<= fields.ShutterHeight.value >%
                }
                isPickable TRUE
              }
            ]
          }
        ]
      }
    }
  ]
  name "robot(1)"
  controller "ShutterController"
  window "shutter_window"

  }
}


